Traceback (most recent call last):

  File "C:\Users\Local_Admin\Desktop\twoPhotonsController\source\application_interface.py", line 680, in goto_motor
    [s.getValue() for s in self.motor_selectors])

  File "C:\Users\Local_Admin\Desktop\twoPhotonsController\source\mouvment_delegate.py", line 106, in goto_position
    self._MOVVEL(Xs, V, checkid=checkid)

  File "C:\Users\Local_Admin\Desktop\twoPhotonsController\source\mouvment_delegate.py", line 225, in _MOVVEL
    self.XY_c.MOVVEL(Xs[:2], V[:2])

  File "C:\Users\Local_Admin\Desktop\twoPhotonsController\source\controllers\stage_controller.py", line 114, in MOVVEL
    l.MOV(1, x)

  File "C:\Users\Local_Admin\Anaconda3\lib\site-packages\pipython-1.3.4.59-py3.6.egg\pipython\gcscommands.py", line 3106, in MOV
    self.__msgs.send(cmdstr)

  File "C:\Users\Local_Admin\Anaconda3\lib\site-packages\pipython-1.3.4.59-py3.6.egg\pipython\gcsmessages.py", line 120, in send
    self.__checkerror(senderr=not self.__embederr)

  File "C:\Users\Local_Admin\Anaconda3\lib\site-packages\pipython-1.3.4.59-py3.6.egg\pipython\gcsmessages.py", line 278, in __checkerror
    raise exc  # Raising NoneType while only classes or instances are allowed pylint: disable=E0702

GCSError: Position out of limits (7)


Unable to move to position

Traceback (most recent call last):

  File "C:\Users\Local_Admin\Desktop\twoPhotonsController\source\application_interface.py", line 680, in goto_motor
    [s.getValue() for s in self.motor_selectors])

  File "C:\Users\Local_Admin\Desktop\twoPhotonsController\source\mouvment_delegate.py", line 106, in goto_position
    self._MOVVEL(Xs, V, checkid=checkid)

  File "C:\Users\Local_Admin\Desktop\twoPhotonsController\source\mouvment_delegate.py", line 226, in _MOVVEL
    self.Z_c.MOVVEL(Xs[2:], V[2:])

  File "C:\Users\Local_Admin\Desktop\twoPhotonsController\source\controllers\stage_controller.py", line 270, in MOVVEL
    self.move_to(X[0])

  File "C:\Users\Local_Admin\Desktop\twoPhotonsController\source\controllers\stage_controller.py", line 317, in move_to
    self._kCubeDCServoMotor.MoveTo(Decimal(float(pos)), timeout);

DeviceMovingException: Device already moving
   at Thorlabs.MotionControl.GenericMotorCLI.AdvancedMotor.GenericAdvancedMotorCLI.VerifyDeviceMovement(Int32 functionDepth, VerifyMovementFlags flags)
   at Thorlabs.MotionControl.GenericMotorCLI.AdvancedMotor.GenericAdvancedMotorCLI.MoveTo(Decimal position, Int32 waitTimeout)




Unable to set shutter time 0.1
Unable to set shutter time 0.09198708369814117


Traceback (most recent call last):

  File "C:\Users\Local_Admin\Desktop\twoPhotonsController\source\application_delegate.py", line 161, in showCameraFrame
    self.imageCanvas.frameshow(frame)

  File "C:\Users\Local_Admin\Desktop\twoPhotonsController\source\application_interface.py", line 80, in frameshow
    self.imshow(im[::2, ::2], vmax = 255)

  File "C:\Users\Local_Admin\Desktop\twoPhotonsController\source\application_interface.py", line 63, in imshow
    self.figure.clear()

  File "C:\Users\Local_Admin\Anaconda3\lib\site-packages\matplotlib\figure.py", line 1089, in clear
    self.clf()

  File "C:\Users\Local_Admin\Anaconda3\lib\site-packages\matplotlib\figure.py", line 1068, in clf
    self.delaxes(ax)         # removes ax from self._axstack

  File "C:\Users\Local_Admin\Anaconda3\lib\site-packages\matplotlib\figure.py", line 819, in delaxes
    self._axstack.remove(a)

  File "C:\Users\Local_Admin\Anaconda3\lib\site-packages\matplotlib\figure.py", line 102, in remove
    Stack.remove(self, self._entry_from_axes(a))

  File "C:\Users\Local_Admin\Anaconda3\lib\site-packages\matplotlib\figure.py", line 97, in _entry_from_axes
    ind, k = dict([(a, (ind, k)) for (k, (ind, a)) in self._elements])[e]

KeyError: <matplotlib.axes._subplots.AxesSubplot object at 0x00000192F515B5F8>

Traceback (most recent call last):

  File "C:\Users\Local_Admin\Desktop\twoPhotonsController\source\application_delegate.py", line 161, in showCameraFrame
    self.imageCanvas.frameshow(frame)

  File "C:\Users\Local_Admin\Desktop\twoPhotonsController\source\application_interface.py", line 80, in frameshow
    self.imshow(im[::2, ::2], vmax = 255)

  File "C:\Users\Local_Admin\Desktop\twoPhotonsController\source\application_interface.py", line 64, in imshow
    self._axes = self.figure.add_subplot(111)

  File "C:\Users\Local_Admin\Anaconda3\lib\site-packages\matplotlib\figure.py", line 1023, in add_subplot
    self._axstack.add(key, a)

  File "C:\Users\Local_Admin\Anaconda3\lib\site-packages\matplotlib\figure.py", line 129, in add
    Stack.remove(self, (key, a_existing))

  File "C:\Users\Local_Admin\Anaconda3\lib\site-packages\matplotlib\cbook.py", line 1396, in remove
    raise ValueError('Unknown element o')

ValueError: Unknown element o

Traceback (most recent call last):

  File "C:\Users\Local_Admin\Desktop\twoPhotonsController\source\coordinates_delegate.py", line 179, in run
    graphs = self.Zcorrector.focus(checkid=self.lockid)

  File "C:\Users\Local_Admin\Desktop\twoPhotonsController\source\position_correctors.py", line 128, in focus
    self.plot(zPos, intensity, size)

  File "C:\Users\Local_Admin\Desktop\twoPhotonsController\source\position_correctors.py", line 89, in plot
    self.ic.draw()

  File "C:\Users\Local_Admin\Anaconda3\lib\site-packages\matplotlib\backends\backend_qt5agg.py", line 176, in draw
    FigureCanvasAgg.draw(self)

  File "C:\Users\Local_Admin\Anaconda3\lib\site-packages\matplotlib\backends\backend_agg.py", line 464, in draw
    self.figure.draw(self.renderer)

  File "C:\Users\Local_Admin\Anaconda3\lib\site-packages\matplotlib\artist.py", line 63, in draw_wrapper
    draw(artist, renderer, *args, **kwargs)

  File "C:\Users\Local_Admin\Anaconda3\lib\site-packages\matplotlib\figure.py", line 1144, in draw
    renderer, self, dsu, self.suppressComposite)

  File "C:\Users\Local_Admin\Anaconda3\lib\site-packages\matplotlib\image.py", line 139, in _draw_list_compositing_images
    a.draw(renderer)

  File "C:\Users\Local_Admin\Anaconda3\lib\site-packages\matplotlib\artist.py", line 63, in draw_wrapper
    draw(artist, renderer, *args, **kwargs)

  File "C:\Users\Local_Admin\Anaconda3\lib\site-packages\matplotlib\axes\_base.py", line 2426, in draw
    mimage._draw_list_compositing_images(renderer, self, dsu)

  File "C:\Users\Local_Admin\Anaconda3\lib\site-packages\matplotlib\image.py", line 139, in _draw_list_compositing_images
    a.draw(renderer)

  File "C:\Users\Local_Admin\Anaconda3\lib\site-packages\matplotlib\artist.py", line 63, in draw_wrapper
    draw(artist, renderer, *args, **kwargs)

  File "C:\Users\Local_Admin\Anaconda3\lib\site-packages\matplotlib\axis.py", line 1136, in draw
    ticks_to_draw = self._update_ticks(renderer)

  File "C:\Users\Local_Admin\Anaconda3\lib\site-packages\matplotlib\axis.py", line 969, in _update_ticks
    tick_tups = [t for t in self.iter_ticks()]

  File "C:\Users\Local_Admin\Anaconda3\lib\site-packages\matplotlib\axis.py", line 969, in <listcomp>
    tick_tups = [t for t in self.iter_ticks()]

  File "C:\Users\Local_Admin\Anaconda3\lib\site-packages\matplotlib\axis.py", line 913, in iter_ticks
    majorTicks = self.get_major_ticks(len(majorLocs))

  File "C:\Users\Local_Admin\Anaconda3\lib\site-packages\matplotlib\axis.py", line 1330, in get_major_ticks
    tick = self.majorTicks[i]

IndexError: list index out of range

